<!DOCTYPE html>
<html lang="en">

<head>
    <meta charset="UTF-8">
    <meta name="viewport" content="width=device-width, initial-scale=1.0">
    <meta http-equiv="X-UA-Compatible" content="ie=edge">
    <title>Promise</title>
</head>

<body>
    <script>
        // getJSON定义
        const getJSON = function (url) {
            const promise = new Promise(function (resolve, reject) {
                const hangdler = function () {
                    if (this.readyState !== 4) {
                        return;
                    }
                    if (this.status === 200) {
                        resolve(this.response)
                    } else {
                        reject(new Error(this.statusText))
                    }
                }
                const client = new XMLHttpRequest();
                client.open('GET', '1简介.md');
                client.onreadystatechange = hangdler;
                client.responseType = 'text';
                client.setRequestHeader('Accept', 'text/plain');
                client.send();

            })
            return promise;
        }
        /* 1.promise的含义
        promise是一个对象,可以获取异步操作的信息,提供统一的api,各种异步操作都可以用同样的方法处理
        -1.对象的状态不受到外界的影响
        -2.一旦状态改变后面将不会再改变,从 pending进行--fulfilled成功--rejected失败 中间的过渡两个状态.状态定了,resolve已经定型.
     */
        /* 2.基本用法 */
        /* resolve函数的作用是，将Promise对象的状态从“未完成”变为“成功”（即从 pending 变为 resolve），在异步操作成功时调用，并将异步操作的结果，作为参数传递出去；
        reject函数的作用是，将Promise对象的状态从“未完成”变为“失败”（即从 pending 变为 rejected），在异步操作失败时调用，并将异步操作报出的错误，作为参数传递出去。 */
        {
            const promise = new Promise((resolve, reject) => {
                // 异步的结果就是传递的参数
                if ( /* 异步操作成功 */ 1) {
                    resolve()
                } else {
                    reject()
                }
            });
            /* promise实例生成之后,可以用then分别指定resolve和rejected的回调函数 */
            promise.then(
                () => {
                    // success function
                },
                () => {
                    // failed function
                }
            )
        }
        {
            function timeout(ms) {
                return new Promise((resolve, reject) => {
                    setTimeout(resolve, ms, 'done');
                })
            }
            timeout(0).then((value) => {
                // console.log(value);
            })
        }
        /* promise创建之后会立即执行 */
        {
            let promise = new Promise((resolve, reject) => {
                // console.log('Promise-76 lines');
                resolve();
            })
            promise.then(() => {
                // console.log('resolve 80 lines');
            }).then(() => {
                // console.log(222, ' 82 lines');
            })
            // 这里有问题
            // .then(() => {
            //     // console.log(333);
            // }).then(() => {
            //     // console.log(333);
            // }).then(() => {
            //     // console.log(333);
            // })
            // console.log(1, '92 lines');
            //Promise
            //1
            //resolve
            //加上前面的done 就是宏微任务的执行顺序
        }
        // 异步加载图片
        {
            function loadImageSync(url) {
                return new Promise((resolve, reject) => {
                    const image = new Image();
                    image.onload = () => {
                        resolve(image)
                    }
                    image.onerror = () => {
                        reject(new Error('Counld not load image at' + url))
                    }
                    image.src = url;
                })
            }
        }
        // Promise 实现ajax
        {
            const getJSON = function (url) {
                const promise = new Promise(function (resolve, reject) {
                    const hangdler = function () {
                        if (this.readyState !== 4) {
                            return;
                        }
                        if (this.status === 200) {
                            resolve(this.response)
                        } else {
                            reject(new Error(this.statusText))
                        }
                    }
                    const client = new XMLHttpRequest();
                    client.open('GET', '1简介.md');
                    client.onreadystatechange = hangdler;
                    client.responseType = 'text';
                    client.setRequestHeader('Accept', 'text/plain');
                    client.send();

                })
                return promise;
            }
            getJSON('/post').then(json => {
                // console.log('Contents' + json, '138 line');
            }, err => {
                // console.log('Error' + err, '140 line');
            })
        }
        // promise也可以作为参数来进行传值,传入的参数决定了另一个promise的状态
        {
            const p1 = new Promise(function (resolve, reject) {

            })
            const p2 = new Promise(function (resolve, reject) {
                resolve(p1)
            })
        } {
            const p1 = new Promise(function (resolve, reject) {
                setTimeout(() => {
                    reject(new Error('fail,p1 154 line'))
                }, 3000);
            })
            const p2 = new Promise(function (resolve, reject) {
                setTimeout(() => {
                    resolve(p1)
                }, 1000);
            })
            p2.then(res => {
                // console.log('res p2 163 line', res);
            }).catch(err => {
                // console.log('err p2 165 line', err);
            })
            // catch也可以捕捉错误
            // p1的状态影响了p2的状态
        }
        /* 调用resolve或者reject,并不会终结promise的参数函数的执行 */
        {
            new Promise((resolve, reject) => {
                resolve(1);
                // console.log(2, '173 line');
            }).then((r) => {
                // console.log(r, '176 line');
            })
            //2
            //1
        }
        /* 主要的函数的内容其实主要是then的回调函数里面的,因此防止意外promise里面最好加上return */
        {
            new Promise((resolve, reject) => {
                return resolve(1)
                // console.log(1);
            });
        }

        /* 3.promise.prototype.then() */
        //promise的then方法返回的还是一个promise的对象,因此可以链式编程
        {

            getJSON('1简介.md').then(json => {
                // console.log(json, '194 line');
            }).then(() => { })
            //函数执行完,执行回调,第一个then执行完之后将返回的值作为参数传给第二个then里面的函数
        }
        /* 多个的then链式编程,如果里面返回的是一个promise对象,就需要等待该promise的对象发生变化,再调用 */
        {
            getJSON('1简介.md').then(post => {
                // 返回promise对象
                return getJSON('1简介.md')
            }).then(function fa(comments) {
                // console.log('resolved 204 line', comments);
            }, function fb(err) {
                // console.log(err);
            })
            // 箭头函数
            getJSON('1简介.md').then(
                post => getJSON('1简介.md')
            ).then(
                comments => {
                    // console.log('resolved 212 line ', comments)
                },
                err => {
                    // console.log(err)
                }
            )
        }
        /* 4.promise.prototype.catch() */
        //promise.prototype.catch是then(null,rejection)的别名,发生错误的回调函数
        //错误来源 主函数里面发生错误 + then里面的resolve函数发生错误
        {
            getJSON('1简介.md').then(
                post => getJSON('1简介.md')
            ).catch(err => {
                // console.log(err);
            })
        }
        //错误来源 主函数里面发生错误 + then里面的resolve函数发生错误
        {
            p = new Promise((resolve, reject) => {

            })

            p.then(val => {
                // console.log(val)).catch(err => // console.log(err)
            })
            // 等价于
            p.then(val => {
                // console.log(val), err => // console.log(err)
            })
        }
        {
            // 例子
            const promise = new Promise(function (resolved, reject) {
                throw new Error('err');
            })
            promise.catch(function (err) {
                // throw的错误被捕获
                // console.log(err, 666);
            })
        }
        {
            // 上面华括弧里面的等价写法
            // 写法1
            const promise = new Promise((resolve, reject) => {
                try {
                    throw new Error('test')
                } catch (error) {
                    reject(error)
                }
            })
            promise.catch(error => {
                // console.log(error, '257 lines');
            })
        }
        {
            // 写法2 
            const promise = new Promise(function (resolve, reject) {
                reject(new Error('test'));
            });
            promise.catch(error => {
                // console.log(error, '266 line');
            })
        }
        /* 如果resolve状态已经变为resolved,那么抛出错误是无法改变  */
        {
            const promise = new Promise(function (resolve, reject) {
                resolve('ok')
                throw new Error('test');
            });
            promise.then(e => {
                // console.log(e, '275 line')
            }).catch(error => {
                // console.log(error, '266 line');
            })
        }
        /* promise的状态一旦改变,后面都将不会改变 */
        /* 上述代码中，promise语句在resolve语句之后再抛出错误，不会被捕获，等于没有抛出错误 。promise对象的错误具有"冒泡"性质,会一直向后传递直到被捕获.也就是说,错误总会被下一个catch捕获.*/
        {
            getJSON('1简介.md').then(function (post) {
                return getJSON(post.commentURL);
            }).then(function (comments) {

            }).catch(function (errors) {
                //三个promise对象.其中任何一个抛出错误都会被catch捕获
                // console.error(errors)
            })
        }
        /* 一般来说,不要在then中定义reject状态的回调函数,应该是用catch方法 */
        {
            const promise = new Promise((res, rej) => {

            })
            // bad
            promise.then(() => { }, () => { })
            // good 
            promise.then(() => { }).catch(() => { })
        }
        /* 与传统的try/catch不同,如果没有使用catch指定错误处理的回调函数,promise对象抛出的错误不会传递到外层 */
        {
            const someAsyncThing = function () {
                return new Promise(function (resolve, reject) {
                    //下面会报错 因为没有声明
                    // resolve(x + 2)
                })
            }
            someAsyncThing().then(function () {
                // console.log('everything is great');
            })
            setTimeout(() => {
                // console.log('ok ok');
            }, 2000);
            /* 报错 => everything is ok => ok ok */
        }
        /* 脚本放在服务器执行 退出码就是0(执行成功) 
            node有unhandledRejection事件专门捕获reject错误
        */
        {
            // process 服务器的node环境会有
            // process.on('unhandledRejection',function (err,p) {
            //     throw err;
            // })
        }
        /* 未来node计划废除unhandledRejection 如果Promise内部有未捕获错误 直接终止程序 进程退出吗不是0*/
        {
            const promise = new Promise((resolve, reject) => {
                resolve('ok')
                /* 在下个循环抛出错误,在Promise函数体外抛出错误 冒泡到最外层 成了未捕获的错误 */
                setTimeout(() => {
                    // throw new Error('test')
                }, 0);
            });
            promise.then(function (value) {
                // console.log(value);
            })
        }
        /* 建议 在Promise对象之后跟catch方法,可以处理promise内部的错误,catch返回的还是promise对象,可以接着调用then方法 */
        {
            const someAsyncThing = function () {
                return new Promise((resolve, reject) => {
                    resolve(x + 6)
                });
            }
            // 有错误就进入catch,没有就不会进入
            someAsyncThing().catch(err => {
                // console.log('there is a error');
            }).then(() => {
                // console.log('carry on');
            })
            /* 但是如果then方法里面报错这个时候就没有与前面的catch无关了 */
        }
        {
            const someAsyncThing = function () {
                return new Promise((resolve, reject) => {
                    resolve(x + 6)
                });
            }
            someAsyncThing().catch(err => {
                // console.log('there is a error');
            }).then(() => {
                // throw 1;
            })
            /* 但是如果then方法里面报错这个时候就没有与前面的catch无关了 */
        }
        /* 在catch方法中,还可以抛出错误 */
        {
            const someOtherAsyncThing = function () { }
            const someAsyncThing = function () {
                return new Promise((resolve, reject) => {
                    resolve(x + 6)
                });
            }
            someAsyncThing().then(function () {
                return someOtherAsyncThing()
            }).catch(error => {
                // console.log('oh error');
                // y * 5
                // y 会报错
            }).then(error => {
                // console.log('carry on');
            })
        }
        {
            const someOtherAsyncThing = function () { }
            const someAsyncThing = function () {
                return new Promise((resolve, reject) => {
                    resolve(x + 6)
                });
            }
            someAsyncThing().then(function () {
                return someOtherAsyncThing()
            }).catch(error => {
                // console.log('oh error');
                y * 5
                // y 会报错,但是后面有catch 因此不会抛出错误
            }).catch(error => {
                // console.log('carry on');
                // 这个catch捕获上一个catch的错误
            })
        }

        /*  Promise.prototype.finally()   */
        /* finally 不管Promise对象最后状态如何 最后都会执行 */
        {
            const promise = new Promise((resolve, reject) => {
            })
            promise.then(result => { }).catch(error => { }).finally(() => { })
        }
        {
            /* 服务器Promise处理请求,使用finally关掉服务器 */
            // server.listen(port).then(()=>{}).finally(server.stop)
        }
        /* finally方法的回调函数不接受任何的参数,也就无法知道前面的Promise状态是fulfilled还是rejected. finally里面的操作与状态无关 
            finally本质上是then方法的特例
        */
        {
            const promise = new Promise((resolve, reject) => { })
            promise.finally(() => { })
            /* 等价于 */
            promise.then(result => result).catch(error => { throw error })
        }
        /* finally 实现原理 */
        {
            Promise.prototype.finally = function (callback) {
                let P = this.constructor;
                /* 不管结果怎么样 都会执行回调函数callback */
                return this.then(
                    value => P.resolve(callback()).then(() => value),
                    reason => P.resolve(callback()).then(() => { throw reason })
                )
            }
        }
        /* finally的返回值是原来的值 */
        {
            // resolve 的值是 undefined
            // Promise.resolve(2).then(() => { }, () => { })
            // resolve 的值是 2
            // Promise.resolve(2).finally(() => { })
            // reject 的值是 undefined
            // Promise.reject(3).then(() => { }, () => { })
            // reject 的值是 3
            // Promise.reject(3).finally(() => { })
            /* 后面有写看后面,前面有写看前面 */
        }

        /* Promise.all() */
        /* Promise.all 方法用于将多个Promise实例包装成一个新的Promise实例 */
        {
            const p1 = new Promise((resolve, reject) => { })
            const p2 = new Promise((resolve, reject) => { })
            const p3 = new Promise((resolve, reject) => { })
            const p = Promise.all([p1, p2, p3])
        }
        /* 
            Promise.all可以接受一个数组,里面是promise实例,如果不是就会执行Promise.resolve方法(Promise.all方法的参数可以不是数组,但是要有Iterator接口.返回的每个成员都是Promise实例)
            p的状态有两种
                p1,p2,p3状态都是fulfilled,p的状态才是fulfilled;
                p1,p2,p3有一个状态是rejected,p的状态就是rejected
        */
        {
            const promises = [2, 3, 5, 7, 11, 13].map(function (id) {
                return getJSON('/post/' + id + '.json')
            })
            Promise.all(promises).then(function (posts) { }).catch(function (err) { })
            // 六个实例的状态都变成fulfilled才会执行then中的函数,否则执行catch中的函数
        }
        {
            // const databasePromise = connectDatabase();

            // const booksPromise = databasePromise
            //     .then(findAllBooks);

            // const userPromise = databasePromise
            //     .then(getCurrentUser);

            // Promise.all([
            //     booksPromise,
            //     userPromise
            // ]).then(([books, user]) => pickTopRecommentations(books, user));

            // 等booksPromise,userPromise这两个的结果都返回了才会执行pickTopRecommentations回调函数
        }
        /* 如果作为参数的Promise实例,自己定义了catch方法,如果被rejected,并不会触发Promise.all()的catch方法 */
        {
            const p1 = new Promise((resolve, reject) => {
                resolve('hello')
            }).then(result => result).catch(e => e)
            const p2 = new Promise((resolve, reject) => {
                // throw new Error('报错了')
            }).then(result => result).catch(e => e)
            Promise.all([p1, p2]).then(result => console.log(result)).catch(e => console.log(e))
        }
        /* 如果没有catch的话就会被Promise.all的catch捕捉 */
        {
            const p1 = new Promise((resolve, reject) => {
                resolve('hello')
            }).then(result => result).catch(e => e)
            const p2 = new Promise((resolve, reject) => {
                // throw new Error('报错了')
            }).then(result => result)
            Promise.all([p1, p2]).then(result => console.log(result)).catch(e => console.log(e))
        }

        /* Promise.case() */
        /* Promise.race方法试讲多个Promise实例包装成一个Promise实例 */
        {
            const p1 = new Promise((resolve, reject) => { })
            const p2 = new Promise((resolve, reject) => { })
            const p3 = new Promise((resolve, reject) => { })
            const p = Promise.race([p1, p2, p3])
            /* 只要p1,p2,p3中有一个实例率先改变,p的状态就跟着改变.那个率先改变的Promise返回的实例就传给p的回调函数 */
        }
        /* 如果传给Promise.race()不是实例,就会先调用Promise.resolve方法,将参数转换为Promise实例 */
        {
            /* 例子:如果一段时间没有获得结果,将Promise的状态变为reject,否则是resolve */
            // const p = Promise.race([
            //     fetch('耗费时间的请求链接'),
            //     new Promise(function (resolve, reject) {
            //         setTimeout(() => {
            //             reject(new Error('request tiemout'))
            //         }, 5000);
            //     })
            // ])
            // p.then(()=>{ console.log(1)}).catch(err=>{console.log(err);})
        }

        /* Promise.resolve */
        /* Promise.resolve将现有对象转换为Promise对象 */
        {
            // const jsPromise=Promise.resolve($.ajax('/whatever.json'));
            // 上述代码将jquery生成的deferred对象转为promise对象
        }
        /* 等价写法 */
        {
            Promise.resolve('foo')
            new Promise(resolve => resolve('foo'))
        }
        /* Promise.resolve方法的参数分成四种情况
            1.参数是Promise实例,就不做任何修改
            2.参数是一个thenable对象
            3.参数不是具有then方法的对象,或者不是对象
            4.不带有任何参数
         */
        /* 参数是一个thenable对象 */
        {
            //  有then方法的对象
            let thenable = {
                then: function (resolve, reject) {
                    //  console.log('立即执行');
                    resolve(42)
                }
            }
            //  promise.resolve将这个对象转换为Promise对象,立即执行thenable中的then方法
            let p1 = Promise.resolve(thenable)
            // p1.then(res=>console.log(res))
        }
        /* 3.参数不是具有then方法的对象,或者根本就不是对象 */
        {
            //  参数为原始值,或者没有then方法的对象,则Promise.resolve方法返回一个新的Promise对象,状态为resolved
            const p = Promise.resolve('hello')
            // p.then(res=>console.log(res))
        }
        /* 4.不带有任何参数 */
        {
            //  Promise.resolve方法允许调用不带参数,直接返回resolved的Promise对象
            // 调用Promise.resolve直接得到promise对象
            const p = Promise.resolve();
            // p.then(()=>{console.log('直接执行resolve')})

        }
        /* 注意:立即resolve的promise对象,实在本轮事件循环event loop结束时,而不是下一轮事件循环的开始*/
        {
            //  一个异步
            setTimeout(() => {
                // console.log(3)
            }, 0);
            //  本轮事件的结束
            Promise.resolve().then(function () {
                // console.log(2)
            })
            // 正常
            // console.log(1)
        }
        /* 9.Promise.reject() */
        /* Promise.reject(reason) 方法返回一个新的Promise实例,该实例的状态为reject */
        {
            // const p1 = Promise.reject('出错了')
            //  等同于
            // const p = new Promise((resolve, reject) => { reject('出错了') })
            // p.then(null, s => { console.log(s) })
            /*上面代码生成了一个Promise对象的实例方法,状态为reject,回调函数立即执行 */
        }
        /* Promise.reject()方法的参数会原封不动地作为reject的理由,变成后续方法的参数 */
        {
            const thenable = {
                then(resolve, reject) {
                    reject('出错了')
                }
            }
            Promise.reject(thenable).catch(e => console.log(e === thenable))
            /* Promise.reject()方法的参数是一个thenable对象,后面的catch接收到的参数就是这个对象,就是 Promise.reject()括号中的内容 */
        }

        /*10.应用  */

    </script>
</body>

</html>
